Workbook
Name _Hlk160088037: TB_CONTENIDO!$A$157
Name _Hlk219801894: TB_CONTENIDO!$A$1
Name _Hlk509415286: TB_CONTENIDO!$A$53
Name _Int_4dZwZgYt: TB_CONTENIDO!$A$2023
Name _Int_bwhai4qf: TB_CONTENIDO!$A$1155
Name _Int_gxGI6NX6: TB_CONTENIDO!$A$2024
Name _Int_hlT4tKsj: TB_CONTENIDO!$A$2025
Name _Int_NdsI6ssT: TB_CONTENIDO!$A$2030
Name _Int_RgTDtiOI: TB_CONTENIDO!$A$2029
Name _Int_UVNgvkK8: TB_CONTENIDO!$A$2028
Name _Toc140848061: TB_CONTENIDO!$A$2584
Name _Toc156210732: TB_CONTENIDO!$A$66
Name _Toc156210735: TB_CONTENIDO!$A$408
Name _Toc205885636: TB_CONTENIDO!$A$628
Name _Toc205885637: TB_CONTENIDO!$A$661
Name _Toc205885644: TB_CONTENIDO!$A$879
Name _Toc205885646: TB_CONTENIDO!$A$886
Name _Toc205885647: TB_CONTENIDO!$A$907
Name _Toc205885648: TB_CONTENIDO!$A$950
Name _Toc205885649: TB_CONTENIDO!$A$1087
Name _Toc205885655: TB_CONTENIDO!$A$1334
Name _Toc205885662: TB_CONTENIDO!$A$1488
Name _Toc205885669: TB_CONTENIDO!$A$1769
Name _Toc205885682: TB_CONTENIDO!$A$1862
Name _Toc205885692: TB_CONTENIDO!$A$2122
Name _Toc205885693: TB_CONTENIDO!$A$2216
Name _Toc205885704: TB_CONTENIDO!$A$2582
Name _Toc205885705: TB_CONTENIDO!$A$2585
Name _Toc205885706: TB_CONTENIDO!$A$2594
Name _Toc205885707: TB_CONTENIDO!$A$2599
Name _Toc205885709: TB_CONTENIDO!$A$2608
Name _Toc205885714: TB_CONTENIDO!$A$2764
Name _Toc219794295: TB_CONTENIDO!$A$108
Name _Toc219794300: TB_CONTENIDO!$A$154
Name _Toc219794304: TB_CONTENIDO!$A$384
Name _Toc227098835: TB_CONTENIDO!$A$55
Name _Toc227098836: TB_CONTENIDO!$A$81
Name _Toc227098837: TB_CONTENIDO!$A$86
Name _Toc227098838: TB_CONTENIDO!$A$89
Name _Toc227098839: TB_CONTENIDO!$A$107
Name _Toc227098840: TB_CONTENIDO!$A$110
Name _Toc227098841: TB_CONTENIDO!$A$121
Name _Toc227098842: TB_CONTENIDO!$A$127
Name _Toc227098843: TB_CONTENIDO!$A$144
Name _Toc227098844: TB_CONTENIDO!$A$150
Name _Toc227098845: TB_CONTENIDO!$A$159
Name _Toc227098846: TB_CONTENIDO!$A$169
Name _Toc227098847: TB_CONTENIDO!$A$188
Name _Toc227098848: TB_CONTENIDO!$A$328
Name _Toc227098850: TB_CONTENIDO!$A$389
Name _Toc227098851: TB_CONTENIDO!$A$392
Name _Toc227098852: TB_CONTENIDO!$A$395
Name _Toc227098854: TB_CONTENIDO!$A$412
Name _Toc227098855: TB_CONTENIDO!$A$416
Name _Toc227098856: TB_CONTENIDO!$A$532
Name _Toc227098857: TB_CONTENIDO!$A$570
Name _Toc227098858: TB_CONTENIDO!$A$575
Name _Toc227098859: TB_CONTENIDO!$A$587
Name _Toc227098860: TB_CONTENIDO!$A$590
Name _Toc227098861: TB_CONTENIDO!$A$593

Sheet INSTRUCCIONES
B2: LISTA DE CHEQUEO — MONITOREO DE INFORMACIÓN DE PROCESOS INSTITUCIONALES
B3: Control C-02 | Proceso: Desempeño Institucional | Gerencia de Planeación y Gestión
B5: PROPÓSITO DEL INSTRUMENTO
B6: Objetivo: | C6: Verificar la calidad, completitud, oportunidad y consistencia de la información reportada por cada proceso fuente al modelo de desempeño institucional e informes de la gerencia, conforme a los protocolos y fichas técnicas de indicadores vigentes.
B7: Alcance: | C7: Aplica a todos los subprocesos reportantes agrupados por Vicerrectoría / Gerencia. Se ejecuta de manera trimestral por el Especialista en Medición y Mejora.
B8: Riesgo mitigado: | C8: R2 — Desempeño institucional gestionado ineficazmente por falta de estandarización, duplicidades y baja calidad de datos. R3 — Limitaciones en procesos manuales de recolección y validación.
B9: Criterio de alerta: | C9: Un proceso se marca en ALERTA si obtiene CUMPLE en menos del 80% de los criterios verificados, o si incumple cualquier criterio marcado como CRÍTICO (★).
B10: Escala de calificación: | C10: CUMPLE ✔ = Criterio satisfecho sin observaciones | CUMPLE PARCIALMENTE ⚠ = Satisfecho con observaciones o brechas menores | NO CUMPLE ✘ = Criterio no satisfecho, requiere acción correctiva | N/A = No aplica al proceso en el período
B11: Frecuencia: | C11: Trimestral — Cortes: Marzo / Junio / Septiembre / Diciembre. Se ejecuta dentro de los primeros 15 días hábiles posteriores al cierre de cada trimestre.
B12: Responsable: | C12: Especialista en Medición y Mejora — Director de estudios internos Gerencia de Planeación y Gestión
B13: Nota sobre escalamiento: | C13: Si se identifican hallazgos críticos (NO CUMPLE en criterio ★), el especialista notifica al responsable del proceso en máximo 3 días hábiles. El plazo de corrección es de 10 días hábiles. Hallazgos sin corrección escalan a C-03.
B15: CONVENCIONES DE COLOR:
B16: Verde claro | C16: Proceso CUMPLE — Sin observaciones relevantes
B17: Amarillo claro | C17: Proceso CUMPLE PARCIALMENTE — Requiere seguimiento
B18: Rojo claro | C18: Proceso NO CUMPLE — Requiere acción correctiva inmediata
B19: Azul muy claro | C19: Fila de encabezado de categoría
B20: Gris claro | C20: Fila de instrucción o referencia

Sheet PORTADA PERÍODO
B2: DATOS DE IDENTIFICACIÓN DEL PERÍODO DE MONITOREO
B4: Año de monitoreo: | C4: 2025
B5: Trimestre / Corte: | C5: T4-Diciembre
B6: Fecha de inicio del monitoreo: | C6: 46054
B7: Fecha de cierre del monitoreo: | C7: 46081
B8: Especialista responsable: | C8: Ximena Silva - Fabricio Lopez
B9: Cargo: | C9: Especialista en Medición y Mejora - Director de estudios internos
B10: Dependencia: | C10: Gerencia de Planeación y Gestión
B11: Versión del instrumento: | C11: v1.0 — 2026
B12: Total procesos monitoreados: | C12: =COUNTA('LISTA DE CHEQUEO'!C5:C157) -> 114
B13: Procesos en ALERTA: | C13: =COUNTIF(RESUMEN!D5:D200,"ALERTA") -> 0
B14: Procesos sin novedad: | C14: =COUNTIF(RESUMEN!D5:D200,"SIN NOVEDAD") -> 0

Sheet LISTA DE CHEQUEO
A1: LISTA DE CHEQUEO — MONITOREO DE CALIDAD DE INFORMACIÓN REPORTADA POR PROCESOS INSTITUCIONALES
A2: Control C-02 | Proceso: Desempeño Institucional | Trimestre: [Ver Portada Período] | Responsable: [Ver Portada Período]
A3: ★ = Criterio CRÍTICO — El incumplimiento activa alerta inmediata independientemente del puntaje global | ✔ CUMPLE ⚠ CUMPLE PARCIALMENTE ✘ NO CUMPLE N/A = No aplica
A5: # | B5: Linea | C5: VICERRECTORÍA / GERENCIA | D5: PROCESO | E5: SUBPROCESO | F5: Tematica | G5: Informe de gestión | H5: Informe de sostenibilidad | I5: I. OPORTUNIDAD (Entrega en tiempo ★) | J5: II. COMPLETITUD (Todos los campos ★) | K5: III. CONSISTENCIA (Coherencia interna) | L5: IV. PRECISIÓN (Cálculo correcto ★) | M5: V. PROTOCOLO (Conforme a ficha) | N5: OBSERVACIONES / HALLAZGOS DETECTADOS | O5: ACCIÓN REQUERIDA / RECOMENDACIÓN | P5: RESPONSABLE PROCESO | Q5: RESULTADO GLOBAL
A6: 1 | B6: Institucional | C6: Gerencia de Planeación y Gestión | D6: DIRECCIONAMIENTO ESTRATÉGICO | E6: Planeación Estratégica | F6: PLANEACIÓN POR RETOS | I6: ✔ CUMPLE | J6: ✔ CUMPLE | K6: ✔ CUMPLE | L6: ✔ CUMPLE | M6: ✔ CUMPLE
A7: 1 | B7: Institucional | C7: Gerencia de Planeación y Gestión | D7: DIRECCIONAMIENTO ESTRATÉGICO | E7: Gestión de proyectos | F7: AGENDA DE PROYECTOS ESTRATÉGICOS | I7: ✔ CUMPLE | J7: ✔ CUMPLE | K7: ✔ CUMPLE | L7: ✔ CUMPLE | M7: ✔ CUMPLE
A8: 1 | B8: Institucional | C8: Gerencia de Planeación y Gestión | D8: DIRECCIONAMIENTO ESTRATÉGICO | E8: Desempeño Institucional | F8: MEDICIÓN DEL DESEMPEÑO A PARTIR DEL CUADRO DE MANDO INTEGRAL ESTRATÉGICO: | I8: ✔ CUMPLE | J8: ✔ CUMPLE | K8: ✔ CUMPLE | L8: ✔ CUMPLE | M8: ✔ CUMPLE
A9: 1 | B9: Institucional | C9: Gerencia de Planeación y Gestión | D9: DIRECCIONAMIENTO ESTRATÉGICO | E9: Planeación Estratégica | F9: PLAN DE MEJORAMIENTO | I9: ✔ CUMPLE | J9: ✔ CUMPLE | K9: ✔ CUMPLE | L9: ✔ CUMPLE | M9: ✔ CUMPLE
A10: 26 | B10: Calidad | C10: Vicerrectoría académica | D10: AUTOEVALUACIÓN Y AUTOREGULACIÓN | E10: Autoevaluación de programas académicos | F10: Acreditación de programas en alta calidad | G10: X | H10: X | I10: ✔ CUMPLE | J10: ✔ CUMPLE | K10: ⚠ CUMPLE PARCIALMENTE | L10: ✔ CUMPLE | M10: ✔ CUMPLE | N10: Diferencias de datos entre Kawak, Informe de sostenibilidad y Informe de gestión
A11: 35 | B11: Calidad | C11: Vicerrectoría académica | D11: AUTOEVALUACIÓN Y AUTOREGULACIÓN | E11: Autoevaluación institucional | F11: Autoevaluación institucional | G11: X | H11: X | I11: ✔ CUMPLE | J11: ✔ CUMPLE | K11: ✔ CUMPLE | L11: ✔ CUMPLE | M11: ✔ CUMPLE
A12: 51 | B12: Calidad | C12: Vicerrectoría académica | D12: DOCENCIA | E12: Gestión de unidades académicas | F12: PEI | G12: X | I12: ✔ CUMPLE | J12: ✔ CUMPLE | K12: ✔ CUMPLE | L12: ✔ CUMPLE | M12: ✔ CUMPLE
A13: 52 | B13: Calidad | C13: Rectoría | D13: GESTIÓN DE PORTAFOLIO INSTITUCIONAL | E13: Diseño de contenido Virtual | F13: Modulos virtuales | I13: ✔ CUMPLE | J13: ✔ CUMPLE | K13: ✘ NO CUMPLE | L13: ✔ CUMPLE | M13: ✔ CUMPLE | N13: Ajustes de información posterior
A14: 51 | B14: Calidad | C14: Vicerrectoría académica | D14: DOCENCIA | E14: Gestión de unidades académicas | F14: Actualización de politicas y reglamentos institucionales | G14: X | H14: X | I14: ✔ CUMPLE | J14: ✔ CUMPLE | K14: ✔ CUMPLE | L14: ✔ CUMPLE | M14: ✔ CUMPLE
A15: 52 | B15: Calidad | C15: Rectoría | D15: GESTIÓN DE PORTAFOLIO INSTITUCIONAL | E15: Diseño de contenido Virtual | F15: Producción audiovisual | I15: ✔ CUMPLE | J15: ✔ CUMPLE | K15: ✘ NO CUMPLE | L15: ✔ CUMPLE | M15: ✔ CUMPLE | N15: Ajustes de información posterior
A16: 28 | B16: Calidad | C16: Vicerrectoría académica | D16: DOCENCIA | E16: Gestión Docente | F16: Evolución de la planta profesoral | G16: X | H16: X | I16: ✔ CUMPLE | J16: ✔ CUMPLE | K16: ⚠ CUMPLE PARCIALMENTE | L16: ✔ CUMPLE | M16: ✔ CUMPLE | N16: Diferencias con boletin | O16: Se solicita ajuste del boletin
A17: 28 | B17: Calidad | C17: Vicerrectoría académica | D17: DOCENCIA | E17: Gestión Docente | F17: Profesores por nivel de formación | G17: X | H17: X | I17: ✔ CUMPLE | J17: ✔ CUMPLE | K17: ✔ CUMPLE | L17: ✔ CUMPLE | M17: ✔ CUMPLE
A18: 28 | B18: Calidad | C18: Vicerrectoría académica | D18: DOCENCIA | E18: Gestión Docente | F18: Evolución de la relación estudiante-docente tce | G18: X | H18: X | I18: ✔ CUMPLE | J18: ✔ CUMPLE | K18: ✔ CUMPLE | L18: ✔ CUMPLE | M18: ✔ CUMPLE
A19: 28 | B19: Calidad | C19: Vicerrectoría académica | D19: DOCENCIA | E19: Gestión Docente | F19: Profesores escalafonados | G19: X | H19: X | I19: ✔ CUMPLE | J19: ✔ CUMPLE | K19: ✔ CUMPLE | L19: ✔ CUMPLE | M19: ✔ CUMPLE
A20: 28 | B20: Calidad | C20: Vicerrectoría académica | D20: DOCENCIA | E20: Gestión Docente | F20: Resultados de evaluación 360 | G20: X | H20: X | I20: ✔ CUMPLE | J20: ✔ CUMPLE | K20: ✔ CUMPLE | L20: ✔ CUMPLE | M20: ✔ CUMPLE
A21: 28 | B21: Calidad | C21: Vicerrectoría académica | D21: DOCENCIA | E21: Gestión Docente | F21: Plan de formación profesoral | G21: X | H21: X | I21: ✔ CUMPLE | J21: ✔ CUMPLE | K21: ✔ CUMPLE | L21: ✔ CUMPLE | M21: ✔ CUMPLE
A22: 51 | B22: Calidad | C22: Vicerrectoría académica | D22: DOCENCIA | E22: Gestión de unidades académicas | F22: Eventos académicos | G22: X | H22: X | I22: ✔ CUMPLE | J22: ✔ CUMPLE | K22: ✔ CUMPLE | L22: ✔ CUMPLE | M22: ✔ CUMPLE
A23: 51 | B23: Calidad | C23: Vicerrectoría académica | D23: DOCENCIA | E23: Gestión de unidades académicas | F23: Consultorías y asesorías | G23: X | H23: X | I23: ✔ CUMPLE | J23: ✔ CUMPLE | K23: ✔ CUMPLE | L23: ✔ CUMPLE | M23: ✔ CUMPLE
A24: 51 | B24: Calidad | C24: Vicerrectoría académica | D24: DOCENCIA | E24: Gestión de unidades académicas | F24: Convenios | G24: X | H24: X | I24: ✔ CUMPLE | J24: ✔ CUMPLE | K24: ✔ CUMPLE | L24: ✔ CUMPLE | M24: ✔ CUMPLE
A25: 10 | B25: Calidad | C25: Vicerrectoría académica | D25: INVESTIGACIÓN, INNOVACIÓN Y CREACIÓN | E25: Investigación, desarrollo tecnológico, innovación y creación | F25: Categorización grupos de investigación | H25: X | I25: ✔ CUMPLE | J25: ✔ CUMPLE | K25: ✘ NO CUMPLE | L25: ✔ CUMPLE | M25: ✔ CUMPLE | N25: Diferencias en las fuentes de información y reporte del proceso
A26: 10 | B26: Calidad | C26: Vicerrectoría académica | D26: INVESTIGACIÓN, INNOVACIÓN Y CREACIÓN | E26: Investigación, desarrollo tecnológico, innovación y creación | F26: Proyectos de investigación | H26: X | I26: ✔ CUMPLE | J26: ✔ CUMPLE | K26: ✘ NO CUMPLE | L26: ✔ CUMPLE | M26: ✔ CUMPLE | N26: Diferencias en las fuentes de información y reporte del proceso
A27: 10 | B27: Calidad | C27: Vicerrectoría académica | D27: INVESTIGACIÓN, INNOVACIÓN Y CREACIÓN | E27: Investigación, desarrollo tecnológico, innovación y creación | F27: Productos de investigación | H27: X | I27: ✔ CUMPLE | J27: ✔ CUMPLE | K27: ✘ NO CUMPLE | L27: ✔ CUMPLE | M27: ✔ CUMPLE | N27: Diferencias en las fuentes de información y reporte del proceso
A28: 10 | B28: Calidad | C28: Vicerrectoría académica | D28: INVESTIGACIÓN, INNOVACIÓN Y CREACIÓN | E28: Investigación, desarrollo tecnológico, innovación y creación | F28: Docentes investigadores | H28: X | I28: ✔ CUMPLE | J28: ✔ CUMPLE | K28: ✔ CUMPLE | L28: ✔ CUMPLE | M28: ✔ CUMPLE
A29: 10 | B29: Calidad | C29: Vicerrectoría académica | D29: INVESTIGACIÓN, INNOVACIÓN Y CREACIÓN | E29: Investigación, desarrollo tecnológico, innovación y creación | F29: Estudiantes en actividades de investigación | H29: X | I29: ✔ CUMPLE | J29: ✔ CUMPLE | K29: ✔ CUMPLE | L29: ✔ CUMPLE | M29: ✔ CUMPLE
A30: 10 | B30: Calidad | C30: Vicerrectoría académica | D30: INVESTIGACIÓN, INNOVACIÓN Y CREACIÓN | E30: Investigación, desarrollo tecnológico, innovación y creación | F30: Participación de estudiantes en eventos cientificos regionales, nacionales e internacionales | H30: X | I30: ✔ CUMPLE | J30: ✔ CUMPLE | K30: ✔ CUMPLE | L30: ✔ CUMPLE | M30: ✔ CUMPLE
A31: 10 | B31: Calidad | C31: Vicerrectoría académica | D31: INVESTIGACIÓN, INNOVACIÓN Y CREACIÓN | E31: Investigación, desarrollo tecnológico, innovación y creación | F31: Centros de investigación y transferencia | H31: X | I31: ✔ CUMPLE | J31: ✔ CUMPLE | K31: ⚠ CUMPLE PARCIALMENTE | L31: ✔ CUMPLE | M31: ✔ CUMPLE | N31: Información del CATI se ajusto por periodos
A32: 10 | B32: Calidad | C32: Vicerrectoría académica | D32: INVESTIGACIÓN, INNOVACIÓN Y CREACIÓN | E32: Investigación, desarrollo tecnológico, innovación y creación | F32: Innovación | H32: X | I32: ✔ CUMPLE | J32: ✔ CUMPLE | K32: ✔ CUMPLE | L32: ✔ CUMPLE | M32: ✔ CUMPLE
A33: 10 | B33: Calidad | C33: Vicerrectoría académica | D33: VISIBILIDAD NACIONAL E INTERNACIONAL | E33: VISIBILIDAD NACIONAL E INTERNACIONAL | F33: Participación de estudiantes en internacionalización del currículo | H33: X | I33: ✔ CUMPLE | J33: ✔ CUMPLE | K33: ✔ CUMPLE | L33: ✔ CUMPLE | M33: ✔ CUMPLE
A34: 10 | B34: Calidad | C34: Vicerrectoría académica | D34: VISIBILIDAD NACIONAL E INTERNACIONAL | E34: VISIBILIDAD NACIONAL E INTERNACIONAL | F34: Movilidad docente | H34: X | I34: ✔ CUMPLE | J34: ✔ CUMPLE | K34: ✔ CUMPLE | L34: ✔ CUMPLE | M34: ✔ CUMPLE
A35: 10 | B35: Calidad | C35: Vicerrectoría académica | D35: VISIBILIDAD NACIONAL E INTERNACIONAL | E35: VISIBILIDAD NACIONAL E INTERNACIONAL | F35: Movilidad de estudiantes | H35: X | I35: ✔ CUMPLE | J35: ✔ CUMPLE | K35: ✔ CUMPLE | L35: ✔ CUMPLE | M35: ✔ CUMPLE
A36: 35 | B36: Calidad | C36: Vicerrectoría académica | D36: GESTIÓN DE PORTAFOLIO INSTITUCIONAL | E36: Autoevaluación de programas académicos | F36: Aprobación de condiciones iniciales de programas académicos | H36: X | I36: ✔ CUMPLE | J36: ✔ CUMPLE | K36: ✔ CUMPLE | L36: ✔ CUMPLE | M36: ✔ CUMPLE
A37: 35 | B37: Calidad | C37: Vicerrectoría académica | D37: GESTIÓN DE PORTAFOLIO INSTITUCIONAL | E37: Autoevaluación de programas académicos | F37: Elaboración de informes de autoevaluación en alta calidad de programas académicos | H37: X | I37: ✔ CUMPLE | J37: ✔ CUMPLE | K37: ✔ CUMPLE | L37: ✔ CUMPLE | M37: ✔ CUMPLE
A38: 35 | B38: Calidad | C38: Vicerrectoría académica | D38: GESTIÓN DE PORTAFOLIO INSTITUCIONAL | E38: Autoevaluación de programas académicos | F38: Procesos de renovación de acreditación en alta calidad de programas académicos | H38: X | I38: ✔ CUMPLE | J38: ✔ CUMPLE | K38: ✔ CUMPLE | L38: ✔ CUMPLE | M38: ✔ CUMPLE
A39: 35 | B39: Calidad | C39: Vicerrectoría académica | D39: GESTIÓN DE PORTAFOLIO INSTITUCIONAL | E39: Creación, modificación y cierre de programas académicos | F39: Portafolio académico | H39: X | I39: ✔ CUMPLE | J39: ✔ CUMPLE | K39: ✔ CUMPLE | L39: ✔ CUMPLE | M39: ✔ CUMPLE
A40: 35 | B40: Calidad | C40: Vicerrectoría académica | D40: GESTIÓN DE PORTAFOLIO INSTITUCIONAL | E40: Creación, modificación y cierre de programas académicos | F40: Nuevos programas con registro calificado aprobado | H40: X | I40: ✔ CUMPLE | J40: ✔ CUMPLE | K40: ✔ CUMPLE | L40: ✔ CUMPLE | M40: ✔ CUMPLE
A41: 35 | B41: Calidad | C41: Vicerrectoría académica | D41: GESTIÓN DE PORTAFOLIO INSTITUCIONAL | E41: Creación, modificación y cierre de programas académicos | F41: Renovación de programas académicos | H41: X | I41: ✔ CUMPLE | J41: ✔ CUMPLE | K41: ⚠ CUMPLE PARCIALMENTE | L41: ✔ CUMPLE | M41: ✔ CUMPLE | N41: Diferencias con Kawak por ajustes en ficha tecnica, Resolución
...

Sheet CONSOLIDADO
A1: Linea | B1: Unidad | C1: PROCESO | D1: SUBPROCESO | E1: Tematica
A2: Institucional | B2: Gerencia de Planeación y Gestión | C2: DIRECCIONAMIENTO ESTRATÉGICO | D2: Planeación Estratégica | E2: Planeación por retos
A3: Institucional | B3: Gerencia de Planeación y Gestión | C3: DIRECCIONAMIENTO ESTRATÉGICO | D3: Gestión de proyectos | E3: Agenda de proyectos estratégicos
A4: Institucional | B4: Gerencia de Planeación y Gestión | C4: DIRECCIONAMIENTO ESTRATÉGICO | D4: Desempeño Institucional | E4: Medición del desempeño a partir del cuadro de mando integral estratégico:
A5: Institucional | B5: Gerencia de Planeación y Gestión | C5: DIRECCIONAMIENTO ESTRATÉGICO | D5: Planeación Estratégica | E5: Plan de mejoramiento
A6: Calidad | B6: Vicerrectoría académica | C6: GESTIÓN DE PORTAFOLIO INSTITUCIONAL | D6: Autoevaluación de programas académicos | E6: Acreditación de programas en alta calidad
A7: Calidad | B7: Vicerrectoría académica | C7: GESTIÓN DE PORTAFOLIO INSTITUCIONAL | D7: Autoevaluación de programas académicos | E7: Aprobación de condiciones iniciales de programas académicos
A8: Calidad | B8: Vicerrectoría académica | C8: GESTIÓN DE PORTAFOLIO INSTITUCIONAL | D8: Autoevaluación de programas académicos | E8: Elaboración de informes de autoevaluación en alta calidad de programas académicos
A9: Calidad | B9: Vicerrectoría académica | C9: GESTIÓN DE PORTAFOLIO INSTITUCIONAL | D9: Autoevaluación de programas académicos | E9: Procesos de renovación de acreditación en alta calidad de programas académicos
A10: Calidad | B10: Vicerrectoría académica | C10: DOCENCIA | D10: Gestión Docente | E10: Evolución de la planta profesoral
A11: Calidad | B11: Vicerrectoría académica | C11: DOCENCIA | D11: Gestión Docente | E11: Profesores por nivel de formación
A12: Calidad | B12: Vicerrectoría académica | C12: DOCENCIA | D12: Gestión Docente | E12: Evolución de la relación estudiante-docente tce
... A110: Calidad | B110: Vicerrectoría académica | C110: INVESTIGACIÓN, INNOVACIÓN Y CREACIÓN | D110: Investigación, desarrollo tecnológico, innovación y creación | E110: Innovación

Sheet CRITERIOS DE VERIFICACIÓN
A1: CRITERIOS DE VERIFICACIÓN — DESCRIPCIÓN DETALLADA DE CADA DIMENSIÓN
A3: DIM. | B3: DIMENSIÓN / CRITERIO | C3: DESCRIPCIÓN — ¿QUÉ VERIFICA? | D3: EVIDENCIA ESPERADA | E3: CRITICO ★ / OBSERVACIONES
A4: I | B4: OPORTUNIDAD (Columna E) ★ CRÍTICO | C4: ¿El proceso entregó la información dentro del plazo establecido en la ficha técnica del indicador o protocolo institucional vigente? • Verificar fecha límite vs. fecha real de entrega. • Retrasos superiores a 3 días hábiles sin justificación = NO CUMPLE. | D4: • Correo/comunicado de entrega con fecha. • Registro en sistema de seguimiento. • Acuse de recibo del especialista. | E4: ★ CRÍTICO — La entrega tardía impide la consolidación del informe trimestral y activa alerta en C-03.
A5: II | B5: COMPLETITUD (Columna F) ★ CRÍTICO | C5: ¿La información reportada contiene todos los campos, indicadores y períodos requeridos según la ficha técnica? • Verificar que no falten indicadores, períodos, numeradores o denominadores. • Campos en blanco no justificados = NO CUMPLE. | D5: • Informe o plantilla de reporte diligenciada sin campos vacíos. • Ficha técnica del indicador como referencia. • Listado de variables requeridas. | E5: ★ CRÍTICO — La ausencia de datos esenciales hace inválido el reporte del proceso.
A6: III | B6: CONSISTENCIA (Columna G) | C6: ¿Los datos reportados son coherentes internamente y no presentan contradicciones con reportes anteriores o fuentes relacionadas? • Comparar con datos del período anterior (variación > 20% sin justificación = hallazgo). • Verificar que numerador no supere denominador donde aplique. | D6: • Reporte del período anterior para comparación. • Justificación escrita ante variaciones atípicas. • Cruce con otras fuentes institucionales. | E6: No crítico — Genera CUMPLE PARCIALMENTE con observación. Requiere seguimiento en el siguiente corte.
A7: IV | B7: PRECISIÓN / EXACTITUD (Columna H) ★ CRÍTICO | C7: ¿Los cálculos, fórmulas y resultados de los indicadores son correctos conforme a la metodología definida en la ficha técnica? • Recalcular manualmente al menos el 20% de los indicadores reportados. • Verificar aplicación correcta de la fórmula de cálculo definida. | D7: • Ficha técnica con fórmula de cálculo. • Hoja de trabajo con recálculo de verificación. • Fuente de datos primaria. | E7: ★ CRÍTICO — Error de cálculo invalida el indicador y genera dato erróneo en el modelo institucional.
A8: V | B8: PROTOCOLO / ESTANDARIZACIÓN (Columna I) | C8: ¿El proceso de recolección y reporte cumple con el protocolo y formato institucional establecido? • Verificar uso de plantilla o formato oficial. • Verificar que el responsable de reporte es el designado en la ficha técnica. • Detectar pasos manuales no estandarizados o dependientes del criterio personal. | D8: • Plantilla oficial utilizada. • Ficha técnica con responsable designado. • Procedimiento o instructivo de recolección. | E8: No crítico — Incumplimientos en protocolo se comunican al responsable y se incluyen en el plan de formación C-04.

Sheet RESUMEN
A1: RESUMEN EJECUTIVO — RESULTADOS DEL MONITOREO TRIMESTRAL
B2: TOTAL PROCESOS MONITOREADOS | C2: SIN NOVEDAD (CUMPLE) | D2: SEGUIMIENTO | E2: ALERTA (NO CUMPLE) | F2: % CUMPLIMIENTO GLOBAL
B3: =COUNTA('LISTA DE CHEQUEO'!E9:E13) -> 5 | C3: =COUNTIF('LISTA DE CHEQUEO'!Q9:Q13,"SIN NOVEDAD") -> 0 | D3: =COUNTIF('LISTA DE CHEQUEO'!Q9:Q13,"SEGUIMIENTO") -> 0 | E3: =COUNTIF('LISTA DE CHEQUEO'!Q9:Q13,"ALERTA") -> 0 | F3: =IF(COUNTA('LISTA DE CHEQUEO'!Q9:Q13)=0,"N/D",TEXT(COUNTIF('LISTA DE CHEQUEO'!Q9:Q13,"SIN NOVEDAD")/COUNTA('LISTA DE CHEQUEO'!Q9:Q13),"0.0%")) -> N/D
A5: DETALLE POR PROCESO — RESULTADO DEL PERÍODO
A6: # | B6: VICERRECTORÍA / GERENCIA | C6: SUBPROCESO / PROCESO FUENTE | D6: RESULTADO GLOBAL | E6: CRITERIOS NO CUMPLIDOS (Resumen) | F6: # HALLAZGOS | G6: ESTADO / OBSERVACIÓN EJECUTIVA
A7: 1 | B7: Vicerrectoría financiera | C7: GESTIÓN DE ABASTECIMIENTO | D7: ='LISTA DE CHEQUEO'!Q9 -> 0 | E7: =COUNTIF('LISTA DE CHEQUEO'!I9:M9,"✘ NO CUMPLE") -> 0 | F7: ='LISTA DE CHEQUEO'!N9 -> 0
A8: 2 | B8: Gerencia de talento humano y comunicaciones | C8: GESTIÓN Y DESARROLLO DEL TALENTO HUMANO | D8: ='LISTA DE CHEQUEO'!#REF! -> #REF! | E8: =COUNTIF('LISTA DE CHEQUEO'!#REF!,"✘ NO CUMPLE") -> #REF! | F8: ='LISTA DE CHEQUEO'!#REF! -> #REF!
A9: 3 | B9: Vicerrectoría del estudiante | C9: GESTIÓN DE LA TECNOLOGÍA E INNOVACIÓN DIGITAL | D9: ='LISTA DE CHEQUEO'!#REF! -> #REF! | E9: =COUNTIF('LISTA DE CHEQUEO'!#REF!,"✘ NO CUMPLE") -> #REF! | F9: ='LISTA DE CHEQUEO'!#REF! -> #REF!
A10: 4 | B10: Gerencia de Planeación y Gestión | C10: AUDITORÍA INTERNA | D10: ='LISTA DE CHEQUEO'!#REF! -> #REF! | E10: =COUNTIF('LISTA DE CHEQUEO'!#REF!,"✘ NO CUMPLE") -> #REF! | F10: ='LISTA DE CHEQUEO'!#REF! -> #REF!
A11: 5 | B11: Gerencia de talento humano y comunicaciones | C11: GESTIÓN DE SEGURIDAD Y SALUD EN EL TRABAJO | D11: ='LISTA DE CHEQUEO'!#REF! -> #REF! | E11: =COUNTIF('LISTA DE CHEQUEO'!#REF!,"✘ NO CUMPLE") -> #REF! | F11: ='LISTA DE CHEQUEO'!#REF! -> #REF!
A12: 6 | B12: Vicerrectoría financiera | C12: Gestión Infraestructura Física | D12: ='LISTA DE CHEQUEO'!#REF! -> #REF! | E12: =COUNTIF('LISTA DE CHEQUEO'!#REF!,"✘ NO CUMPLE") -> #REF! | F12: ='LISTA DE CHEQUEO'!#REF! -> #REF!
A13: 7 | B13: Gerencia de Planeación y Gestión | C13: Gestión de calidad | D13: ='LISTA DE CHEQUEO'!#REF! -> #REF! | E13: =COUNTIF('LISTA DE CHEQUEO'!#REF!,"✘ NO CUMPLE") -> #REF! | F13: ='LISTA DE CHEQUEO'!#REF! -> #REF!
A14: 8 | B14: Vicerrectoría académica | C14: VISIBILIDAD NACIONAL E INTERNACIONAL | D14: ='LISTA DE CHEQUEO'!#REF! -> #REF! | E14: =COUNTIF('LISTA DE CHEQUEO'!#REF!,"✘ NO CUMPLE") -> #REF! | F14: ='LISTA DE CHEQUEO'!#REF! -> #REF!
A15: 9 | B15: Vicerrectoría académica | C15: Biblioteca Institucional | D15: ='LISTA DE CHEQUEO'!#REF! -> #REF! | E15: =COUNTIF('LISTA DE CHEQUEO'!#REF!,"✘ NO CUMPLE") -> #REF! | F15: ='LISTA DE CHEQUEO'!#REF! -> #REF!
A16: 10 | B16: Vicerrectoría académica | C16: Investigación, desarrollo tecnológico, innovación y creación | D16: ='LISTA DE CHEQUEO'!#REF! -> #REF! | E16: =COUNTIF('LISTA DE CHEQUEO'!#REF!,"✘ NO CUMPLE") -> #REF! | F16: ='LISTA DE CHEQUEO'!#REF! -> #REF!
A17: 11 | B17: Vicerrectoría académica | C17: Formación para la investigación, creación e innovación | D17: ='LISTA DE CHEQUEO'!#REF! -> #REF! | E17: =COUNTIF('LISTA DE CHEQUEO'!#REF!,"✘ NO CUMPLE") -> #REF! | F17: ='LISTA DE CHEQUEO'!#REF! -> #REF!
A18: 12 | B18: Vicerrectoría académica | C18: Editorial y Publicaciones | D18: ='LISTA DE CHEQUEO'!#REF! -> #REF! | E18: =COUNTIF('LISTA DE CHEQUEO'!#REF!,"✘ NO CUMPLE") -> #REF! | F18: ='LISTA DE CHEQUEO'!#REF! -> #REF!
A19: 13 | B19: Vicerrectoría del estudiante | C19: Servicio | D19: ='LISTA DE CHEQUEO'!#REF! -> #REF! | E19: =COUNTIF('LISTA DE CHEQUEO'!#REF!,"✘ NO CUMPLE") -> #REF! | F19: ='LISTA DE CHEQUEO'!#REF! -> #REF!
... A31: 25 | B31: Vicerrectoría académica | C31: Centro de Medios Audiovisuales | D31: ='LISTA DE CHEQUEO'!#REF! -> #REF! | E31: =COUNTIF('LISTA DE CHEQUEO'!#REF!,"✘ NO CUMPLE") -> #REF! | F31: ='LISTA DE CHEQUEO'!#REF! -> #REF!
A32: 26 | B32: Vicerrectoría académica | C32: Autoevaluación de programas académicos | D32: ='LISTA DE CHEQUEO'!Q10 -> 0 | E32: =COUNTIF('LISTA DE CHEQUEO'!I10:M10,"✘ NO CUMPLE") -> 0 | F32: ='LISTA DE CHEQUEO'!N10 -> Diferencias de datos entre Kawak, Informe de sostenibilidad y Informe de gestión
A33: 27 | B33: Vicerrectoría del estudiante | C33: EXPERIENCIA INSTITUCIONAL | D33: ='LISTA DE CHEQUEO'!#REF! -> #REF! | E33: =COUNTIF('LISTA DE CHEQUEO'!#REF!,"✘ NO CUMPLE") -> #REF! | F33: ='LISTA DE CHEQUEO'!#REF! -> #REF!
A34: 28 | B34: Vicerrectoría académica | C34: Gestión Docente | D34: ='LISTA DE CHEQUEO'!#REF! -> #REF! | E34: =COUNTIF('LISTA DE CHEQUEO'!#REF!,"✘ NO CUMPLE") -> #REF! | F34: ='LISTA DE CHEQUEO'!#REF! -> #REF!
A35: 29 | B35: Vicerrectoría del estudiante | C35: Cultura y Deporte | D35: ='LISTA DE CHEQUEO'!#REF! -> #REF! | E35: =COUNTIF('LISTA DE CHEQUEO'!#REF!,"✘ NO CUMPLE") -> #REF! | F35: ='LISTA DE CHEQUEO'!#REF! -> #REF!
A36: 30 | B36: Gerencia de Planeación y Gestión | C36: GESTIÓN DE RIESGOS | D36: ='LISTA DE CHEQUEO'!#REF! -> #REF! | E36: =COUNTIF('LISTA DE CHEQUEO'!#REF!,"✘ NO CUMPLE") -> #REF! | F36: ='LISTA DE CHEQUEO'!#REF! -> #REF!
A37: 31 | B37: Vicerrectoría financiera | C37: Administración de Servicios Generales | D37: ='LISTA DE CHEQUEO'!#REF! -> #REF! | E37: =COUNTIF('LISTA DE CHEQUEO'!#REF!,"✘ NO CUMPLE") -> #REF! | F37: ='LISTA DE CHEQUEO'!#REF! -> #REF!
A38: 32 | B38: Vicerrectoría del estudiante | C38: Servicio de Salud | D38: ='LISTA DE CHEQUEO'!#REF! -> #REF! | E38: =COUNTIF('LISTA DE CHEQUEO'!#REF!,"✘ NO CUMPLE") -> #REF! | F38: ='LISTA DE CHEQUEO'!#REF! -> #REF!
A39: 33 | B39: Vicerrectoría académica | C39: Creación, modificación y cierre de programas académicos | D39: ='LISTA DE CHEQUEO'!#REF! -> #REF! | E39: =COUNTIF('LISTA DE CHEQUEO'!#REF!,"✘ NO CUMPLE") -> #REF! | F39: ='LISTA DE CHEQUEO'!#REF! -> #REF!
A40: 34 | B40: Vicerrectoría académica | C40: Gestión de Graduados | D40: ='LISTA DE CHEQUEO'!#REF! -> #REF! | E40: =COUNTIF('LISTA DE CHEQUEO'!#REF!,"✘ NO CUMPLE") -> #REF! | F40: ='LISTA DE CHEQUEO'!#REF! -> #REF!
A41: 35 | B41: Vicerrectoría académica | C41: Autoevaluación institucional | D41: ='LISTA DE CHEQUEO'!#REF! -> #REF! | E41: =COUNTIF('LISTA DE CHEQUEO'!#REF!,"✘ NO CUMPLE") -> #REF! | F41: ='LISTA DE CHEQUEO'!#REF! -> #REF!
A42: 36 | B42: Vicerrectoría financiera | C42: Contabilidad | D42: ='LISTA DE CHEQUEO'!#REF! -> #REF! | E42: =COUNTIF('LISTA DE CHEQUEO'!#REF!,"✘ NO CUMPLE") -> #REF! | F42: ='LISTA DE CHEQUEO'!#REF! -> #REF!
A43: 37 | B43: Vicerrectoría del estudiante | C43: DATOS Y ANALÍTICA | D43: ='LISTA DE CHEQUEO'!#REF! -> #REF! | E43: =COUNTIF('LISTA DE CHEQUEO'!#REF!,"✘ NO CUMPLE") -> #REF! | F43: ='LISTA DE CHEQUEO'!#REF! -> #REF!
A44: 38 | B44: Vicerrectoría financiera | C44: Tesorería | D44: ='LISTA DE CHEQUEO'!#REF! -> #REF! | E44: =COUNTIF('LISTA DE CHEQUEO'!#REF!,"✘ NO CUMPLE") -> #REF! | F44: ='LISTA DE CHEQUEO'!#REF! -> #REF!
... A56: 50 | B56: Gerencia de talento humano y comunicaciones | C56: Comunicaciones Internas | D56: ='LISTA DE CHEQUEO'!#REF! -> #REF! | E56: =COUNTIF('LISTA DE CHEQUEO'!#REF!,"✘ NO CUMPLE") -> #REF! | F56: ='LISTA DE CHEQUEO'!#REF! -> #REF!
A57: 51 | B57: Vicerrectoría académica | C57: Gestión de unidades académicas | D57: ='LISTA DE CHEQUEO'!Q12 -> 0 | E57: =COUNTIF('LISTA DE CHEQUEO'!I12:M12,"✘ NO CUMPLE") -> 0 | F57: ='LISTA DE CHEQUEO'!N12 -> 0
A58: 52 | B58: Rectoría | C58: Diseño de contenido Virtual | D58: ='LISTA DE CHEQUEO'!Q13 -> 0 | E58: =COUNTIF('LISTA DE CHEQUEO'!I13:M13,"✘ NO CUMPLE") -> 1 | F58: ='LISTA DE CHEQUEO'!N13 -> Ajustes de información posterior

Sheet HALLAZGOS Y ACCIONES
A1: REGISTRO DE HALLAZGOS Y PLAN DE ACCIÓN — C-02 / C-03
A2: Registre aquí cada hallazgo identificado en la Lista de Chequeo. Este registro activa automáticamente el seguimiento de C-03 para los incumplimientos de indicadores.
A4: # | B4: PROCESO FUENTE | C4: SUBPROCESO | D4: DIMENSIÓN INCUMPLIDA | E4: DESCRIPCIÓN DEL HALLAZGO | F4: CRITICIDAD | G4: ACCIÓN CORRECTIVA REQUERIDA | H4: RESPONSABLE PROCESO | I4: PLAZO MÁXIMO | J4: ESTADO
A5: 1
A6: 2
A7: 3
A8: 4
A9: 5
A10: 6
A11: 7
A12: 8
A13: 9
A14: 10
A15: 11
A16: 12
... A34: 30

Sheet HISTÓRICO
A1: HISTÓRICO DE MONITOREOS — TRAZABILIDAD POR PROCESO Y PERÍODO
A2: Al cerrar cada ciclo trimestral, copie los resultados de 'RESUMEN' como valores en esta hoja para preservar el histórico. No vincule fórmulas — copie como valores.
A4: # | B4: TRIMESTRE | C4: VICERRECTORÍA / GERENCIA | D4: SUBPROCESO / PROCESO | E4: RESULTADO GLOBAL | F4: # HALLAZGOS CRÍTICOS | G4: # HALLAZGOS TOTALES | H4: ACCIÓN ACTIVADA (C-03) | I4: FORMACIÓN REQUERIDA (C-04) | J4: OBSERVACIONES
A5: 1
A6: 2
A7: 3
A8: 4
A9: 5
A10: 6
A11: 7
A12: 8
A13: 9
A14: 10
A15: 11
A16: 12
... A64: 60

Sheet PROCESO
A1: Unidad | B1: Proceso | C1: Subproceso | D1: Tipo de proceso
A2: Vicerrectoría financiera y administrativa | B2: GESTIÓN DE ABASTECIMIENTO | C2: GESTIÓN DE ABASTECIMIENTO | D2: APOYO
A3: Gerencia de talento humano y comunicaciones | B3: GESTIÓN Y DESARROLLO DEL TALENTO HUMANO | C3: GESTIÓN Y DESARROLLO DEL TALENTO HUMANO | D3: ESTRATÉGICO
A4: Vicerrectoría del estudiante | B4: GESTIÓN DE LA TECNOLOGÍA E INNOVACIÓN DIGITAL | C4: GESTIÓN DE LA TECNOLOGÍA E INNOVACIÓN DIGITAL | D4: APOYO
A5: Gerencia de Planeación y Gestión | B5: AUDITORÍA INTERNA | C5: AUDITORÍA INTERNA | D5: EVALUACIÓN Y MEJORA
A6: Gerencia de talento humano y comunicaciones | B6: GESTIÓN DE SEGURIDAD Y SALUD EN EL TRABAJO | C6: GESTIÓN DE SEGURIDAD Y SALUD EN EL TRABAJO | D6: APOYO
A7: Vicerrectoría financiera y administrativa | B7: INFRAESTRUCTURA Y SERVICIOS ADMINISTRATIVOS | C7: Gestión Infraestructura Física | D7: APOYO
A8: Gerencia de Planeación y Gestión | B8: PLANIFICACIÓN Y MEJORA DEL SISTEMA INTEGRADO | C8: Gestión de calidad | D8: EVALUACIÓN Y MEJORA
A9: Vicerrectoría académica | B9: VISIBILIDAD NACIONAL E INTERNACIONAL | C9: VISIBILIDAD NACIONAL E INTERNACIONAL | D9: MISIONAL
A10: Vicerrectoría académica | B10: RECURSOS ACADÉMICOS Y DE INVESTIGACIÓN | C10: Biblioteca Institucional | D10: MISIONAL
A11: Vicerrectoría académica | B11: INVESTIGACIÓN, INNOVACIÓN Y CREACIÓN | C11: Investigación, desarrollo tecnológico, innovación y creación | D11: MISIONAL
A12: Vicerrectoría académica | B12: INVESTIGACIÓN, INNOVACIÓN Y CREACIÓN | C12: Formación para la investigación, creación e innovación | D12: MISIONAL
... A53: Rectoría | B53: GESTIÓN DE PORTAFOLIO INSTITUCIONAL | C53: Diseño de contenido Virtual | D53: MISIONAL

Sheet TB_CONTENIDO
A1: 1. Tabla de contenido
A2: MENSAJE DEL RECTOR A LOS GRUPOS DE INTERÉS | B2: 3
A3: MATERIALIDAD | B3: 7
A4: 1.12.6 | B4: DIRECCIONAMIENTO ESTRATÉGICO | C4: 25
A5: 1.12.7. | B5: MEJORA CONTINUA INSTITUCIONAL | C5: 35
A6: 1.12.8. | B6: POLISIGS (Sistema Integrado de Aseguramiento y Gestión Para la Sostenibilidad) | C6: 37
A7: 1.12.9. | B7: PLAN DE MEJORAMIENTO | C7: 38
A8: 2. | B8: LÍNEA ESTRATÉGICA CALIDAD | C8: 40
A9: 2.1 | B9: OBJETIVO ESTRATÉGICO: ASEGURAR LA ALTA CALIDAD | C9: 41
A10: 2.1.1 ACTUALIZACIÓN DEL PROYECTO EDUCATIVO INSTITUCIONAL - PEI: UN EJERCICIO COLECTIVO, PARTICIPATIVO Y TRANSFORMADOR | B10: 41
A11: 2.1.2 ACTUALIZACIÓN DE POLÍTICAS Y REGLAMENTOS INSTITUCIONALES | B11: 42
A12: 2.1.3 ACREDITACIÓN INSTITUCIONAL EN ALTA CALIDAD | B12: 42
A13: 2.1.4 ACREDITACIÓN DE PROGRAMAS EN ALTA CALIDAD | B13: 44
A14: 2.1.4.1 APROBACIÓN DE CONDICIONES INICIALES DE PROGRAMAS ACADÉMICOS. | B14: 44
A15: 2.1.4.2. ELABORACIÓN DE INFORMES DE AUTOEVALUACIÓN EN ALTA CALIDAD DE PROGRAMAS ACADÉMICOS | B15: 45
A16: 2.1.4.3. PROCESOS DE RENOVACIÓN DE ACREDITACIÓN EN ALTA CALIDAD DE PROGRAMAS ACADÉMICOS | B16: 45
A17: 2.1.5 Afiliación ASCUN | B17: 46
A18: 2.1.6 | B18: DOCENCIA | C18: 46
A19: 2.1.7 | B19: FORTALECIMIENTO DE LA GESTIÓN DE INVESTIGACIÓN, INNOVACIÓN Y CREACIÓN | C19: 53
A20: 2.1.8 | B20: FORTALECIMIENTO DE LA INTERNACIONALIZACIÓN | C20: 60
A21: 2.1.9 | B21: EVENTOS ACADÉMICOS | C21: 64
A22: 2.1.10 | B22: CONSULTORÍAS Y ASESORÍAS | C22: 67
A23: 2.1.11 | B23: RECONOCIMIENTOS | C23: 69
A24: 2.1.12 | B24: CONVENIOS | C24: 71
A25: 2.1.13 | B25: CONSOLIDACIÓN DEL CREA (CENTRO DE RECURSOS Y EXPERIENCIAS PARA EL APRENDIZAJE) | C25: 71
A26: 2.1.13.1 | B26: SISTEMA NACIONAL DE BIBLIOTECAS | C26: 75
A27: 2.1.13.2 | B27: EDITORIAL | C27: 81
A28: 2.1.13.3 | B28: CMA | C28: 83
A29: 2.2 OBJETIVO ESTRATÉGICO: FORTALECER LA OFERTA EDUCATIVA Y LA INNOVACIÓN CURRICULAR | B29: 84
A30: 2.2.1 | B30: APROBACIÓN DE CONDICIONES INSTITUCIONALES PARA REGISTRO CALIFICADO | C30: 84
A31: 2.2.2 | B31: AMPLIACIÓN Y SOSTENIMIENTO DE LA OFERTA ACADÉMICA | C31: 85
A32: 2.2.3 | B32: FORTALECIMIENTO CURRICULAR | C32: 87
A33: Ø | B33: Proceso de gestión, evaluación e innovación curricular | C33: 87
A34: 2.2.4 | B34: MODELO DE RESULTADOS DE APRENDIZAJE | C34: 91
A35: 2.2.5 | B35: GERENCIA DE EDUCACIÓN VIRTUAL | C35: 92
A36: Ø | B36: Diseño de contenido virtual | C36: 93
A37: 3. | B37: LÍNEA ESTRATÉGICA EXPANSIÓN | C37: 93
A38: 3.1 OBJETIVO ESTRATÉGICO: CRECER CON COMPROMISO SOCIAL | B38: 93
A39: 3.1.1 | B39: CRECIMIENTO DE LA POBLACIÓN ESTUDIANTIL | C39: 94
A40: 3.1.1.1 | B40: ESTUDIANTES NUEVOS | C40: 94
...
